<?xml version="1.0"?>
<robot name="myfirst">

  <material name="blue">
    <color rgba="0.0 0.0 1.0 1.0" />
  </material>
  <material name="white">
    <color rgba="1.0 1.0 1.0 1.0" />
  </material>
  <material name="black">
    <color rgba="0.0 0.0 0.0 1.0" />
  </material>

  <link name="base_link" />
  <joint name="base2wrist" type="fixed">
    <parent link="base_link" />
    <child link="wrist" />
    <origin xyz="0 0 0" rpy="0 0 0" />
  </joint>


  <link name="wrist">
    <visual>
      <geometry>
        <mesh filename="package://k3hand_ros/urdf/k3_urdf/wrist.dae" />
        <!-- <cylinder length="0.06" radius="0.025" /> -->
      </geometry>
      <origin xyz="0 0 0" rpy="0 0 0" />
    </visual>
    <collision>
      <geometry>
        <cylinder length="0.06" radius="0.025" />
      </geometry>
    </collision>
    <!-- <inertial> -->
    <!--   <mass value="10"/> -->
    <!--   <inertia ixx="1.0" ixy="0.0" ixz="0.0" iyy="1.0" iyz="0.0" izz="1.0"/> -->
    <!-- </inertial> -->
  </link>
  <link name="thumb_met">
    <visual>
      <geometry>
        <mesh filename="package://k3hand_ros/urdf/k3_urdf/thumb_met.dae" />
      </geometry>
      <origin xyz="0.0 0.0 0.0" />
    </visual>
    <collision>
      <geometry>
        <box size="0.0225 0.035 0.012" />
      </geometry>
      <origin xyz="0.0 0.015 0.0" />
    </collision>
    <inertial>
      <mass value="10" />
      <inertia ixx="1.0" ixy="0.0" ixz="0.0" iyy="1.0" iyz="0.0" izz="1.0" />
    </inertial>
  </link>
  <link name="thumb_middle_1">
    <visual>
      <geometry>
        <mesh filename="package://k3hand_ros/urdf/k3_urdf/thumb_middle_1.dae" />
      </geometry>
      <origin xyz="0.0 0.0 0.0" />
    </visual>
    <collision>
      <geometry>
        <box size="0.0225 0.045 0.012" />
      </geometry>
      <origin xyz="0.0 0.0175 0.0" />
    </collision>
    <inertial>
      <mass value="10" />
      <inertia ixx="1.0" ixy="0.0" ixz="0.0" iyy="1.0" iyz="0.0" izz="1.0" />
    </inertial>
  </link>
  <link name="thumb_middle_2">
    <visual>
      <geometry>
        <mesh filename="package://k3hand_ros/urdf/k3_urdf/thumb_middle_2.dae" />
      </geometry>
      <origin xyz="0.0 0.0 0.0" />
    </visual>
    <collision>
      <geometry>
        <box size="0.0225 0.045 0.012" />
      </geometry>
      <origin xyz="0.0 0.0175 0.0" />
    </collision>
    <inertial>
      <mass value="10" />
      <inertia ixx="1.0" ixy="0.0" ixz="0.0" iyy="1.0" iyz="0.0" izz="1.0" />
    </inertial>
  </link>


  <link name="thumb_tip">
    <visual>
      <geometry>
        <mesh filename="package://k3hand_ros/urdf/k3_urdf/thumb_tip.dae" />
      </geometry>
      <origin xyz="0.0 0.0 0.0" />
    </visual>
    <collision>
      <geometry>
        <box size="0.0225 0.040 0.012" />
      </geometry>
      <origin xyz="0.0 0.015 0.0" />
    </collision>
    <inertial>
      <mass value="10" />
      <inertia ixx="1.0" ixy="0.0" ixz="0.0" iyy="1.0" iyz="0.0" izz="1.0" />
    </inertial>
  </link>

  <link name="fing_met_1">
    <visual>
      <geometry>
        <mesh filename="package://k3hand_ros/urdf/k3_urdf/fing_met_1.dae" />
        <!-- <box size="0.020 0.030 0.012" /> -->
      </geometry>
      <origin xyz="0.022 0.0175 0.00" rpy="0.0 0.0 0.0" />
    </visual>
    <collision>
      <geometry>
        <box size="0.020 0.030 0.012" />
      </geometry>
      <origin xyz="-0.005 -0.010 0.0" />
    </collision>

    <inertial>
      <mass value="10" />
      <inertia ixx="1.0" ixy="0.0" ixz="0.0" iyy="1.0" iyz="0.0" izz="1.0" />
    </inertial>
  </link>
  <link name="fing_middle_1">
    <visual>
      <geometry>
        <mesh filename="package://k3hand_ros/urdf/k3_urdf/fing_middle_1.dae" />
      </geometry>
      <origin xyz="0.0 0.0 0.0" />
    </visual>
    <collision>
      <geometry>
        <box size="0.020 0.120 0.012" />
      </geometry>
      <origin xyz="0.005 -0.050 0.0" />
    </collision>
    <inertial>
      <mass value="10" />
      <inertia ixx="1.0" ixy="0.0" ixz="0.0" iyy="1.0" iyz="0.0" izz="1.0" />
    </inertial>
  </link>

  <link name="fing_met_2">
    <visual>
      <geometry>
        <mesh filename="package://k3hand_ros/urdf/k3_urdf/fing_met_2.dae" />
      </geometry>
      <origin xyz="0.0 0.0 0.0" />
    </visual>
    <collision>
      <geometry>
        <box size="0.020 0.030 0.012" />
      </geometry>
      <origin xyz="0.005 -0.010 0.0" />
    </collision>
    <inertial>
      <mass value="10" />
      <inertia ixx="1.0" ixy="0.0" ixz="0.0" iyy="1.0" iyz="0.0" izz="1.0" />
    </inertial>
  </link>
  <link name="fing_middle_2">
    <visual>
      <geometry>
        <mesh filename="package://k3hand_ros/urdf/k3_urdf/fing_middle_2.dae" />
      </geometry>
      <origin xyz="0.0 0.0 0.0" />
    </visual>
    <collision>
      <geometry>
        <box size="0.020 0.120 0.012" />
      </geometry>
      <origin xyz="-0.005 -0.050 0.0" />
    </collision>
    <inertial>
      <mass value="10" />
      <inertia ixx="1.0" ixy="0.0" ixz="0.0" iyy="1.0" iyz="0.0" izz="1.0" />
    </inertial>
  </link>
  <joint name="joint0" type="revolute">
    <axis xyz="0.0 1.0 0.0" />
    <parent link="wrist" />
    <child link="fing_met_1" />
    <origin xyz="0.0225 -0.0175 0.00" rpy="0.0 1.570796 0.0" />
    <limit lower="-1.570796" upper="0.523599" effort="0.0" velocity="0.0" />
  </joint>
  <joint name="joint1" type="revolute">
    <axis xyz="1.0 0.0 0" />
    <parent link="fing_met_1" />
    <child link="fing_middle_1" />
    <origin xyz="0.000 -0.020 0.0" rpy="-1.570796 0.0 0.0" />
    <limit lower="-1.570796" upper="1.579796" effort="0.0" velocity="0.0" />
  </joint>
  <joint name="joint2" type="revolute">
    <axis xyz="0.0 0.0 1.0" />
    <parent link="wrist" />
    <child link="fing_met_2" />
    <origin xyz="-0.020 -0.015 0.020" rpy="0.0 0.0 -1.570796" />
    <limit lower="-0.523599" upper="1.570796" effort="0.0" velocity="0.0" />
  </joint>
  <joint name="joint3" type="revolute">
    <axis xyz="-1.0 0.0 0" />
    <parent link="fing_met_2" />
    <child link="fing_middle_2" />
    <origin xyz="0.000 -0.020 0.0" rpy="-1.570796 0.0 0.0" />
    <limit lower="-1.570796" upper="1.570796" effort="0.0" velocity="0.0" />
  </joint>
  <joint name="joint4" type="revolute">
    <axis xyz="0.0 0 -1" />
    <parent link="wrist" />
    <child link="thumb_met" />
    <origin rpy="0.78537 0 0" xyz="0 0.02 0" />
    <limit lower="-1.570796" upper="1.570796" effort="30.0" velocity="1.0" />
  </joint>
  <transmission name="joint_fin1_1_trans">
    <type>transmission_interface/SimpleTransmission</type>
    <actuator name="$joint_fin1_1_motor">
      <mechanicalReduction>1</mechanicalReduction>
    </actuator>
    <joint name="joint4">
      <hardwareInterface>hardware_interface/PositionJointInterface</hardwareInterface>
    </joint>
  </transmission>
  <joint name="joint5" type="revolute">
    <axis xyz="1 0.0 0.0" />
    <parent link="thumb_met" />
    <child link="thumb_middle_1" />
    <origin rpy="-0.78537 0 0" xyz="0 0.0 0" />
    <limit lower="-0.8726646" upper="2.268928" effort="0.0" velocity="0.0" />
  </joint>
  <joint name="joint6" type="revolute">
    <axis xyz="1 0.0 0.0" />
    <parent link="thumb_middle_1" />
    <child link="thumb_middle_2" />
    <origin rpy="0 0 0" xyz="0 0.0 0" />
    <limit lower="-1.570796" upper="1.570796" effort="0.0" velocity="0.0" />
  </joint>
  <joint name="joint7" type="revolute">
    <axis xyz="1 0.0 0.0" />
    <parent link="thumb_middle_2" />
    <child link="thumb_tip" />
    <origin rpy="0 0 0" xyz="0 0 0" />
    <limit lower="-1.570796" upper="1.570796" effort="0.0" velocity="0.0" />
  </joint>

</robot>